<?xml version="1.0"?>
<robot name="mcflurry" xmlns:xacro="http://www.ros.org/wiki/xacro">

  <!-- This is the building of the robot -->
  <!-- This is basic. Use this as reference for making future robots -->

  
  <!-- Chassis link -->
  <link name="link_chassis">
    <!-- pose and inertial-->
    <pose>0 0 0.1 0 0 0</pose> <!-- where is the robot at in its environment -->
    <inertial>
	<mass value="2.5" />
	<origin rpy="0 0 0" xyz="0 0 0.8" /> <!-- roll, pitch, yaw and the xyz-->
	<inertia ixx="0.0395416666667" ixy="0" ixz="0.106288333333" iyz="0" izz="0.106288333333" />
    </inertial>
    
    <!-- body -->

    <collision name="collision_chassis">
      <geometry>
	<box size="0.3 0.15 0.07" />
      </geometry>
    </collision>
    <visual>
      <origin rpy="0 0 0" xyz="0 0 0" />
      <geometry>
	<box size="0.3 0.15 0.07" />
      </geometry>
      <material name="blue" /> <!-- For Rviz visualization -->
    </visual>
  </link>

  <!-- Castor front link -->
  <link name="caster_wheel">
    <inertial>
	<mass value="0.05" />
	<origin rpy="0 0 0" xyz="0 0 0" />
	<inertia ixx="0.0395416666667" ixy="0" ixz="0.106288333333" iyz="0" izz="0.106288333333" />
    </inertial>
    <collision name="castor_front_collision">
	<origin rpy="0 0 0" xyz="-0.250 0 0.0095"/>
	<geometry>
	  <sphere radius="0.25"/>
	</geometry>
	<surface>
	  <friction>
	    <ode>
		<mu>0</mu>
		<mu2>0</mu2>
		<slip1>1.0</slip1>
		<slip2>1.0</slip2>
	    </ode>
	  </friction>
	</surface>
    </collision>
    <visual name="castor_front_visual">
	<origin rpy="0 0 0" xyz="0 0 -0.05" />
	<geometry>
	  <sphere radius="0.05"/>
	</geometry>
    </visual>
  </link>
  
  <!-- Joint between caster and chassis-->
  <joint name="joint_caster" type="fixed">
    <origin rpy="0 0 0" xyz="0.2 0 -0.0"/>
    <child link="caster_wheel"/>
    <parent link="link_chassis"/>
  </joint>

  <!-- Right Wheel-->
  <link name="link_right_wheel">
    <inertial>
	<mass value="0.2"/>
	<origin rpy="0 1.5707 1.5707" xyz="0 0 0"/>
	<inertia ixx="0.000526666666667" ixy="0" ixz="0" iyy="0.000526666666667" iyz="0" izz="0.000526666666667"/>
    </inertial>
    <collision name="link_right_wheel_collision">
      <origin rpy="0 1.5707 1.5707" xyz="0 0 0"/>
      <geometry>
	<cylinder length="0.04" radius="0.065" />
      </geometry>
    </collision>
    <visual name="link_right_wheel_visual">
      <origin rpy="0 1.5707 1.5707" xyz="0 0 0" />
      <geometry>
	<cylinder length="0.04" radius="0.1" />
      </geometry>
    </visual>
  </link>
  
  <!-- Joint between right wheel and chassis-->
  <joint name="joint_right_wheel" type="continuous">
    <origin rpy="0 0 0" xyz="0.05 0.15 0"/>
    <child link="link_right_wheel"/>
    <parent link="link_chassis"/>
    <axis rpy="0 0 0" xyz="0 1 0"/>
    <limit effort="10000" velocity="1000"/>
    <joint properties damping = "1.0" friction="1.0"/>
  </joint>

  <!-- Left Wheel-->
  <link name="link_left_wheel">
    <inertial>
	<mass value="0.2"/>
	<origin rpy="0 1.5707 1.5707" xyz="0 0 0"/>
	<inertia ixx="0.000526666666667" ixy="0" ixz="0" iyy="0.000526666666667" iyz="0" izz="0.000526666666667"/>
    </inertial>
    <collision name="link_left_wheel_collision">
      <origin rpy="0 1.5707 1.5707" xyz="0 0 0"/>
      <geometry>
	<cylinder length="0.04" radius="0.065" />
      </geometry>
    </collision>
    <visual name="link_left_wheel_visual">
      <origin rpy="0 1.5707 1.5707" xyz="0 0 0" />
      <geometry>
	<cylinder length="0.04" radius="0.1" />
      </geometry>
    </visual>
  </link>

  <!-- Joint between left wheel and chassis -->
  <joint name="joint_left_wheel" type="continuous">
    <origin rpy="0 0 0" xyz="-0.05 -0.15 0"/> <!-- -y here because of left wheel-->
    <child link="link_left_wheel"/>
    <parent link="link_chassis"/>
    <axis rpy="0 0 0" xyz="0 1 0"/>
    <limit effort="10000" velocity="1000"/>
    <joint properties damping = "1.0" friction="1.0"/>
  </joint>
</robot>
